Workbook

Sheet 1
A2: Moneda: Euro
A3: PAGAMENT MENSUAL + LIQUIDACIÓ
A4: DEL 01/02/26 AL 28/02/26 | D4: 000002 | E4: 000006 | F4: 000007 | G4: 000010 | H4: 000017 | I4: 000027 | J4: 000028 | K4: 000029 | L4: 000065 | M4: 000073 | N4: 000141 | O4: 000148 | P4: 000152 | Q4: 000163 | R4: 000183 | S4: 000185 | T4: 000231 | U4: 000234 | V4: 000245 | W4: 000255 | X4: 000257 | Y4: 000261 | Z4: 000263 | AA4: 000270 | AB4: 000271 | AC4: 000274 | AD4: 000278 | AE4: 000290 | AF4: 000500 | AG4: 000502 | AH4: 001013 | AI4: 001019 | AJ4: 001021 | AK4: 001023 | AL4: 001032 | AM4: 001056 | AN4: 001057 | AO4: 001059 | AP4: 001060 | AQ4: 001139 | AR4: 010004 | AS4: 010014 | AT4: 010019 | AU4: 010023 | AV4: 010073 | AW4: 010077 | AX4: 010079 | AY4: 100010 | AZ4: 100047 | BA4: 100054 | BB4: 100058 | BC4: 100065 | BD4: 100118 | BE4: 100120 | BF4: 100131 | BG4: 100138 | BH4: 100145 | BI4: 100163 | BJ4: 100180 | BK4: 100183 | BL4: 100218 | BM4: 100222 | BN4: 100247 | BO4: 100248 | BP4: 100251 | BQ4: 100256 | BR4: 100267 | BS4: 100271 | BT4: 100272 | BU4: 100284 | BV4: 100295 | BW4: 100296 | BX4: 100302 | BY4: 100303 | BZ4: 100328 | CA4: 100362 | CB4: 100387 | CC4: 100389 | CD4: 100403 | CE4: 100408 | CF4: 100410 | CG4: 100422 | CH4: 100426 | CI4: 100428 | CJ4: 100429 | CK4: 100430 | CL4: 100431 | CM4: 100433 | CN4: 100477 | CO4: 100479 | CP4: 100484 | CQ4: 100487 | CR4: 100505 | CS4: 100509 | CT4: 100512 | CU4: 100514 | CV4: 100520 | CW4: 100525 | CX4: 100526 | CY4: 100529 | CZ4: 100530 | DA4: 100531 | DB4: 100532 | DC4: 100533 | DD4: 100534 | DE4: 100535 | DF4: 100536 | DG4: 100537 | DH4: 100538 | DI4: 100539 | DJ4: 100540 | DK4: 100541 | DL4: 100542
A5: Empresa: 350-PEIXOS PUIGNAU S.A. NIF: A17216359 | D5: FERNANDEZ | E5: SUCARRAT | F5: GARCIA | G5: VIDAL | H5: CORNELLA | I5: RIBAS | J5: OLMO | K5: CORNELLA | L5: HORTA | M5: RODOVAY | N5: BONET | O5: OLIVERAS | P5: PUIGNAU | Q5: PLAJA | R5: MASDEVALL | S5: PUJOL | T5: CUFFI | U5: ESCOBAR | V5: CALERO | W5: NJENTHIEU | X5: COULIBALY | Y5: DARBOE | Z5: TKEMALADZE | AA5: FOFANA | AB5: BALDEH | AC5: HERNANDEZ | AD5: JALLOW | AE5: CORNELLA | AF5: PUIGNAU | AG5: PUIGNAU | AH5: GUERIN | AI5: CABARROCAS | AJ5: ISAAC | AK5: CEJUDO | AL5: TOURE | AM5: CAMPS | AN5: SAN NICOLAS | AO5: MATEO | AP5: NUALART | AQ5: GANO | AR5: OUEDRAOGO | AS5: CLAVER | AT5: ESPAÑOL | AU5: DOMINGUES | AV5: BLANCO | AW5: LERAT | AX5: OFKIR | AY5: LOPEZ | AZ5: ABDOUL | BA5: MUÑOZ | BB5: DABO | BC5: SOUNKALO | BD5: SELGA | BE5: TEJERO | BF5: BABA | BG5: DRAME | BH5: ROIG | BI5: DIALLO | BJ5: CROUS | BK5: FERNANDEZ | BL5: OMEDES | BM5: DAMIAN | BN5: MBALLO | BO5: MAGIRAGA | BP5: DIARRA | BQ5: GOUEM | BR5: BARBOSA | BS5: LUQUE | BT5: SOLA | BU5: GASSAMA | BV5: CAMARA | BW5: REYES | BX5: MONTIEL | BY5: EL | BZ5: TKEMALADZE | CA5: PUIGNAU | CB5: LLEIXA | CC5: PEREZ | CD5: DUCA | CE5: SILLAH | CF5: AIT | CG5: BARRIOS | CH5: CASADEMONT | CI5: PEDRAZA | CJ5: PIÑAR | CK5: GARCIA | CL5: ANDREOTTI | CM5: MAHAMADOU | CN5: RAMIREZ | CO5: GRACIA | CP5: VALLEJOS | CQ5: SILVA | CR5: BAGUE | CS5: KWAKU | CT5: AKHACHIOU | CU5: OLIVA | CV5: FERNANDEZ | CW5: DIALLO | CX5: DIALLO | CY5: NIMAGA | CZ5: GALEAS | DA5: GOMEZ | DB5: KHOUYAOUI | DC5: SALADELAFONT | DD5: ROGER | DE5: VARGAS | DF5: CEESAY | DG5: REDONDO | DH5: OSORTO | DI5: DIAWARA | DJ5: WAGGEH | DK5: PIJOAN | DL5: AGUILERA
D6: GALVEZ | E6: ORTIZ | F6: HERRERA | G6: RAINS | H6: GENER | I6: SITJA | J6: SERRANO | K6: PUIG | L6: VALLS | M6: GONZALEZ | N6: FABIENNE | O6: CARRERAS | P6: CORNELLA | Q6: MORE | R6: ROCA | S6: TORREDEFLOT | T6: SOT | U6: VALLE | V6: YAÑEZ | W6: GERVAIS | X6: OUMAR | Y6: KARIM | Z6: MIKHEILI | AA6: YAHYA | AB6: MUHAMADOU | AC6: ARQUERO | AD6: YUNUSA | AE6: PONT | AF6: MIAS | AG6: MIAS | AH6: LAURENT | AI6: PEIRO | AJ6: VAZQUEZ | AK6: MARQUEZ | AL6: BOUBACAR | AM6: PONS | AN6: HERNANDEZ | AO6: RAMIREZ | AP6: BOIX | AQ6: DEMBA | AR6: ADAMA | AS6: CLAVERO | AT6: PUBILL | AU6: VERRUGA | AV6: CUENCA | AW6: CERVERA | AX6: YOUSSEF | AY6: GONZALEZ | AZ6: RAHIM | BA6: CABALLERO | BB6: KONATÉ | BC6: DENA | BD6: MOLINE | BE6: RODRIGUEZ | BF6: SOUKOUNA | BG6: FOUSSENY | BH6: MARTIN | BI6: ABDOULLAY | BJ6: SOY | BK6: SABIO | BL6: RIGAU | BM6: VILLEGAS | BN6: MAMADOU | BO6: MOHAMADOU | BP6: INCHY | BQ6: TIDIANE | BR6: SOLE | BS6: NADAL | BT6: SOLE | BU6: BAKARY | BV6: BABA | BW6: GIMENEZ | BX6: MACIAS | BY6: JADDAOUI | BZ6: GIORGI | CA6: I | CB6: PLAJA | CC6: QUILEZ | CD6: GHEORGHE-ROB | CE6: JAMBARA | CF6: OUARAB | CG6: ROPERO | CH6: RIFA | CI6: PASCUAL | CJ6: ILLA | CK6: CABA | CL6: NARDI | CM6: BALDE | CN6: GARBEY | CO6: RETORTILLO | CP6: VILLALBA | CQ6: SILVA | CR6: GARCIA-CONSU | CS6: ASIEDU | CT6: ABDERRAHIM | CU6: ALVAREZ | CV6: FERNANDEZ | CW6: KASSIM | CX6: DIAKITE | CY6: SULAYMANE | CZ6: FERRERA | DA6: RUIZ | DB6: AYOUB | DC6: DIAZ | DD6: I | DE6: AURORA | DF6: SANKAREH | DG6: I | DH6: RODAS | DI6: DJIBRIL | DJ6: MAMADOU | DK6: BUSSOT | DL6: SAMITIER
D7: YOLANDA | E7: DANIEL JOSE | F7: SUSANA | G7: DAVID | H7: GERARD | I7: ELENA | J7: NICOLAS | K7: ANGEL | L7: JUAN | M7: ALBERTO | O7: SERGI | P7: MARC | Q7: EDUARDO | R7: JOAN | S7: JORDI | T7: JORDI | U7: ANTONI | V7: BEATRIZ | AC7: XAVIER | AE7: FRANCESC XAV | AF7: JOSE | AG7: LLIBORI | AH7: GERARD | AI7: ROSA MARIA | AJ7: DANIEL | AK7: FELIPE ELADI | AM7: FRANCESC X | AN7: ALEJANDRO | AO7: EUFEMIO | AP7: CARLA | AS7: EVA | AT7: MERITXELL | AU7: LUDOVICO JOA | AV7: ALBERTO | AW7: JEAN MARIE | AY7: IZAN | AZ7: COMPAORE | BA7: BRIAN | BB7: FODE ASSANE | BD7: JAUME | BE7: DAVID | BF7: MADI | BH7: MONTSERRAT | BJ7: LIDIA | BK7: MARIO | BL7: PAULA | BM7: PAU | BR7: ANNA | BS7: RAUL | BT7: ROBERT | BW7: FRANCISCO | BX7: ALFONSO | BY7: BOUJATTOUY S | CA7: PONT, ORIOL | CB7: JOAN | CC7: ALEXANDRE | CE7: SAIHOU | CF7: LUCIA | CG7: ARIADNA | CH7: ORIOL | CI7: AITANA | CJ7: DAVID | CK7: MARIA TERESA | CL7: MARIA MARCEL | CN7: YORLENIS ORL | CO7: POL | CP7: EDWARD JAIR | CQ7: ANTONIO | CR7: CARLES | CS7: EMMANUEL | CU7: MARIA CARMEN | CV7: BRUNO | CX7: SAIBOU MALIC | CZ7: LORENA MARIS | DA7: SERGIO | DC7: ANNA | DD7: CUBERO, JACO | DE7: JONATAN | DF7: ABOU | DG7: PERTEGAS, GE | DH7: ANA | DK7: LLUIS | DL7: DANIEL
A9: CONCEPTE
B11: 1 | C11: SALARI BASE | D11: 1118.22 | E11: 1217.66 | F11: 81.18 | G11: 1118.22 | H11: 1118.22 | I11: 559.11 | J11: 1217.66 | K11: 410.01 | L11: 1217.66 | M11: 894.58 | N11: 1217.66 | O11: 1217.66 | P11: 1635.41 | Q11: 1118.22 | R11: 1433.47 | S11: 1217.66 | T11: 454.28 | U11: 1217.66 | V11: 1118.22 | W11: 1051.32 | X11: 1118.22 | Y11: 1051.32 | Z11: 1118.22 | AA11: 1217.66 | AB11: 770.97 | AC11: 857.3 | AD11: 1118.22 | AE11: 1217.66 | AF11: 1635.41 | AG11: 1635.41 | AH11: 1217.66 | AI11: 1051.32 | AJ11: 1217.66 | AK11: 40.59 | AM11: 1514.28 | AN11: 1051.32 | AO11: 1217.66 | AP11: 1217.66 | AQ11: 1217.66 | AR11: 735.92 | AS11: 1217.66 | AT11: 1118.22 | AU11: 1051.32 | AV11: 1514.28 | AW11: 1217.66 | AX11: 931.85 | AY11: 1118.22 | AZ11: 1051.32 | BA11: 1217.66 | BC11: 1051.32 | BD11: 838.67 | BE11: 1217.66 | BG11: 1051.32 | BH11: 1118.22 | BI11: 1051.32 | BJ11: 1051.32 | BK11: 1217.66 | BL11: 1433.47 | BM11: 1433.47 | BN11: 1051.32 | BO11: 1051.32 | BP11: 876.1 | BQ11: 1051.32 | BR11: 1118.22 | BS11: 1217.66 | BT11: 1514.28 | BU11: 1051.32 | BV11: 700.88 | BW11: 1118.22 | BX11: 1217.66 | BY11: 1118.22 | BZ11: 1118.22 | CA11: 1217.66 | CB11: 1433.47 | CC11: 1217.66 | CD11: 1118.22 | CE11: 1051.32 | CF11: 1051.32 | CG11: 1051.32 | CH11: 1433.47 | CI11: 1051.32 | CJ11: 1051.32 | CK11: 1051.32 | CL11: 1051.32 | CM11: 1051.32 | CN11: 1051.32 | CO11: 35.04 | CP11: 1051.32 | CQ11: 649.43 | CR11: 1051.32 | CS11: 1051.32 | CT11: 946.19 | CU11: 1051.32 | CV11: 1051.32 | CW11: 1051.32 | CX11: 514.4 | CY11: 1051.32 | CZ11: 788.49 | DA11: 1118.22 | DB11: 1118.22 | DC11: 1051.32 | DD11: 1514.28 | DE11: 820.03 | DF11: 665.84 | DG11: 820.03 | DH11: 700.88 | DI11: 665.84 | DJ11: 665.84 | DK11: 447.29 | DL11: 121.77
B12: 13 | C12: OBERTURA NOVA BOTIGA | D12: 80
B13: 74 | C13: PRESENCIA I IMATGE | D13: 34.07 | E13: 34.07 | F13: 2.27 | G13: 34.07 | H13: 34.07 | I13: 34.07 | J13: 34.07 | K13: 12.49 | L13: 34.07 | M13: 27.26 | N13: 34.07 | O13: 34.07 | P13: 34.07 | Q13: 34.07 | R13: 34.07 | S13: 34.07 | T13: 34.07 | U13: 34.07 | V13: 34.07 | W13: 34.07 | X13: 34.07 | Y13: 34.07 | Z13: 34.07 | AA13: 34.07 | AB13: 24.98 | AC13: 26.12 | AD13: 34.07 | AE13: 34.07 | AF13: 34.07 | AG13: 34.07 | AH13: 34.07 | AI13: 34.07 | AJ13: 34.07 | AK13: 1.14 | AM13: 34.07 | AN13: 34.07 | AO13: 34.07 | AP13: 34.07 | AQ13: 34.07 | AR13: 23.85 | AS13: 34.07 | AT13: 34.07 | AU13: 34.07 | AV13: 34.07 | AW13: 34.07 | AX13: 28.39 | AY13: 34.07 | AZ13: 34.07 | BA13: 34.07 | BC13: 34.07 | BD13: 34.07 | BE13: 34.07 | BG13: 34.07 | BH13: 34.07 | BI13: 34.07 | BJ13: 34.07 | BK13: 34.07 | BL13: 34.07 | BM13: 34.07 | BN13: 34.07 | BO13: 34.07 | BP13: 28.39 | BQ13: 34.07 | BR13: 34.07 | BS13: 34.07 | BT13: 34.07 | BU13: 34.07 | BV13: 22.71 | BW13: 34.07 | BX13: 34.07 | BY13: 34.07 | BZ13: 34.07 | CA13: 34.07 | CB13: 34.07 | CC13: 34.07 | CD13: 34.07 | CE13: 34.07 | CF13: 34.07 | CG13: 34.07 | CH13: 34.07 | CI13: 34.07 | CJ13: 34.07 | CK13: 34.07 | CL13: 34.07 | CM13: 34.07 | CN13: 34.07 | CO13: 1.14 | CP13: 34.07 | CR13: 34.07 | CS13: 34.07 | CT13: 30.66 | CU13: 34.07 | CV13: 34.07 | CW13: 34.07 | CY13: 34.07 | CZ13: 34.07 | DA13: 34.07 | DB13: 34.07 | DC13: 34.07 | DD13: 34.07 | DE13: 24.98 | DF13: 21.58 | DG13: 24.98 | DH13: 22.71 | DI13: 21.58 | DJ13: 21.58 | DK13: 13.63 | DL13: 3.41
B14: 75 | C14: PLUS PERILLOSITAT | AK14: 8.21 | AN14: 217.62 | AZ14: 400 | BW14: 200 | BX14: 217.62 | CC14: 251.52 | CN14: 363.98
B15: 84 | C15: PLUS UTILITZ I MANT.MÀQU | AK15: 0.72 | AN15: 21.53 | AZ15: 21.53 | BK15: 21.53 | CC15: 21.53 | CN15: 21.53
B16: 85 | C16: PLUS RESPONSABILITAT | I16: 80 | W16: 150 | X16: 200 | Y16: 100 | AC16: 150 | AJ16: 350 | AM16: 1000 | AO16: 100 | AQ16: 133.33 | AR16: 80.5 | AY16: 150 | AZ16: 150 | BG16: 225 | BQ16: 100 | CC16: 420 | CT16: 100 | CW16: 100
B17: 93 | C17: PLUS DISPONIBILITAT | F17: 5.07 | AP17: 88.74 | AQ17: 112 | BL17: 114.4 | BM17: 133.33 | BS17: 80 | BT17: 216.67 | CB17: 150 | CC17: 93.33
B18: 113 | C18: REGULARITZACIO | R18: 153.46 | T18: 27 | AA18: 125 | AJ18: 191.71 | AO18: 250 | AP18: 150 | AQ18: 166.67 | BJ18: 125 | BK18: 166.66 | BS18: 183.33 | CL18: 100
B19: 123 | C19: ACCIDENT CONVENI | D19: 0.77 | E19: 0.77 | F19: 0.77 | G19: 0.77 | H19: 0.77 | I19: 0.77 | J19: 0.77 | K19: 0.77 | L19: 0.77 | M19: 0.62 | N19: 0.77 | O19: 0.77 | P19: 0.77 | Q19: 0.77 | R19: 0.77 | S19: 0.77 | T19: 0.77 | U19: 0.77 | V19: 0.77 | W19: 0.77 | X19: 0.77 | Y19: 0.77 | Z19: 0.77 | AA19: 0.77 | AB19: 0.56 | AC19: 0.59 | AD19: 0.77 | AE19: 0.77 | AH19: 0.77 | AI19: 0.77 | AJ19: 0.77 | AK19: 0.13 | AM19: 0.77 | AN19: 0.77 | AO19: 0.77 | AP19: 0.77 | AQ19: 0.77 | AR19: 0.54 | AS19: 0.77 | AT19: 0.77 | AU19: 0.77 | AV19: 0.77 | AW19: 0.77 | AX19: 0.64 | AY19: 0.77 | AZ19: 0.77 | BA19: 0.77 | BC19: 0.77 | BD19: 0.77 | BE19: 0.77 | BG19: 0.77 | BH19: 0.77 | BI19: 0.77 | BJ19: 0.77 | BK19: 0.77 | BL19: 0.77 | BM19: 0.77 | BN19: 0.77 | BO19: 0.77 | BP19: 0.64 | BQ19: 0.77 | BR19: 0.77 | BS19: 0.77 | BT19: 0.77 | BU19: 0.77 | BV19: 0.51 | BW19: 0.77 | BX19: 0.77 | BY19: 0.77 | BZ19: 0.77 | CA19: 74.46 | CB19: 0.77 | CC19: 0.77 | CD19: 0.77 | CE19: 0.77 | CF19: 0.77 | CG19: 0.77 | CH19: 0.77 | CI19: 0.77 | CJ19: 0.77 | CK19: 0.77 | CL19: 0.77 | CM19: 0.77 | CN19: 0.77 | CO19: 0.03 | CP19: 0.77 | CR19: 0.77 | CS19: 0.77 | CT19: 0.69 | CU19: 0.77 | CV19: 0.77 | CW19: 0.77 | CY19: 0.77 | CZ19: 0.77 | DA19: 0.77 | DB19: 0.77 | DC19: 0.77 | DD19: 0.77 | DE19: 0.72 | DF19: 0.77 | DG19: 0.77 | DH19: 0.77 | DI19: 0.77 | DJ19: 0.77 | DK19: 0.77 | DL19: 0.77
B20: 131 | C20: MILLORA SALARIAL ABSORBI | D20: 282.22 | H20: 78.28 | I20: 12.61 | O20: 174.67 | P20: 1116.87 | Q20: 28.07 | R20: 1181.86 | Z20: 25.22 | AC20: 19.34 | AF20: 1081.72 | AM20: 2108.62 | AQ20: 549.44 | AS20: 741.34 | AT20: 120.44 | AV20: 2588 | AY20: 36.43 | BE20: 591.34 | BT20: 2412.78 | DD20: 2028.31
B21: 152 | C21: VEHICLE | AG21: 579.58
B22: 171 | C22: MILLORA VOLUNTARIA ABSOR | CB22: 946.44
B23: 173 | C23: PP PAGA ESTIU | D23: 93.18 | E23: 101.47 | F23: 6.76 | G23: 93.18 | H23: 93.18 | I23: 46.59 | J23: 101.47 | K23: 34.17 | L23: 101.47 | M23: 74.55 | N23: 101.47 | O23: 101.47 | P23: 136.28 | Q23: 93.18 | R23: 119.45 | S23: 101.47 | T23: 37.86 | U23: 101.47 | V23: 93.18 | W23: 87.61 | X23: 93.18 | Y23: 87.61 | Z23: 93.18 | AA23: 101.47 | AB23: 64.24 | AC23: 71.44 | AD23: 93.18 | AE23: 101.47 | AF23: 136.28 | AG23: 136.28 | AH23: 101.47 | AI23: 87.61 | AJ23: 101.47 | AK23: 3.38 | AM23: 126.18 | AN23: 87.61 | AO23: 101.47 | AP23: 101.47 | AQ23: 101.47 | AR23: 61.32 | AS23: 101.47 | AT23: 93.18 | AU23: 87.61 | AV23: 126.18 | AW23: 101.47 | AX23: 77.65 | AY23: 93.18 | AZ23: 87.61 | BA23: 101.47 | BC23: 87.61 | BD23: 69.89 | BE23: 101.47 | BG23: 87.61 | BH23: 93.18 | BI23: 87.61 | BJ23: 87.61 | BK23: 101.47 | BL23: 119.45 | BM23: 119.45 | BN23: 87.61 | BO23: 87.61 | BP23: 73.01 | BQ23: 87.61 | BR23: 93.18 | BS23: 101.47 | BT23: 126.18 | BU23: 87.61 | BV23: 58.4 | BW23: 93.18 | BX23: 101.47 | BY23: 93.18 | BZ23: 93.18 | CA23: 101.47 | CB23: 119.45 | CC23: 101.47 | CD23: 93.18 | CE23: 87.61 | CF23: 87.61 | CG23: 87.61 | CH23: 119.45 | CI23: 87.61 | CJ23: 87.61 | CK23: 87.61 | CL23: 87.61 | CM23: 87.61 | CN23: 87.61 | CO23: 2.92 | CP23: 87.61 | CR23: 87.61 | CS23: 87.61 | CT23: 78.85 | CU23: 87.61 | CV23: 87.61 | CW23: 87.61 | CY23: 87.61 | CZ23: 65.7 | DA23: 93.18 | DB23: 93.18 | DC23: 87.61 | DD23: 126.18 | DE23: 68.33 | DF23: 55.48 | DG23: 68.33 | DH23: 58.4 | DI23: 55.48 | DJ23: 55.48 | DK23: 37.27 | DL23: 10.15
B24: 174 | C24: PP PAGA NADAL | D24: 93.18 | E24: 101.47 | F24: 6.76 | G24: 93.18 | H24: 93.18 | I24: 46.59 | J24: 101.47 | K24: 34.17 | L24: 101.47 | M24: 74.55 | N24: 101.47 | O24: 101.47 | P24: 136.28 | Q24: 93.18 | R24: 119.45 | S24: 101.47 | T24: 37.86 | U24: 101.47 | V24: 93.18 | W24: 87.61 | X24: 93.18 | Y24: 87.61 | Z24: 93.18 | AA24: 101.47 | AB24: 64.24 | AC24: 71.44 | AD24: 93.18 | AE24: 101.47 | AF24: 136.28 | AG24: 136.28 | AH24: 101.47 | AI24: 87.61 | AJ24: 101.47 | AK24: 3.38 | AM24: 126.18 | AN24: 87.61 | AO24: 101.47 | AP24: 101.47 | AQ24: 101.47 | AR24: 61.32 | AS24: 101.47 | AT24: 93.18 | AU24: 87.61 | AV24: 126.18 | AW24: 101.47 | AX24: 77.65 | AY24: 93.18 | AZ24: 87.61 | BA24: 101.47 | BC24: 87.61 | BD24: 69.89 | BE24: 101.47 | BG24: 87.61 | BH24: 93.18 | BI24: 87.61 | BJ24: 87.61 | BK24: 101.47 | BL24: 119.45 | BM24: 119.45 | BN24: 87.61 | BO24: 87.61 | BP24: 73.01 | BQ24: 87.61 | BR24: 93.18 | BS24: 101.47 | BT24: 126.18 | BU24: 87.61 | BV24: 58.4 | BW24: 93.18 | BX24: 101.47 | BY24: 93.18 | BZ24: 93.18 | CA24: 101.47 | CB24: 119.45 | CC24: 101.47 | CD24: 93.18 | CE24: 87.61 | CF24: 87.61 | CG24: 87.61 | CH24: 119.45 | CI24: 87.61 | CJ24: 87.61 | CK24: 87.61 | CL24: 87.61 | CM24: 87.61 | CN24: 87.61 | CO24: 2.92 | CP24: 87.61 | CR24: 87.61 | CS24: 87.61 | CT24: 78.85 | CU24: 87.61 | CV24: 87.61 | CW24: 87.61 | CY24: 87.61 | CZ24: 65.7 | DA24: 93.18 | DB24: 93.18 | DC24: 87.61 | DD24: 126.18 | DE24: 68.33 | DF24: 55.48 | DG24: 68.33 | DH24: 58.4 | DI24: 55.48 | DJ24: 55.48 | DK24: 37.27 | DL24: 10.15
B25: 175 | C25: PP PAGA BENEFICIS | D25: 93.18 | E25: 101.47 | F25: 6.76 | G25: 93.18 | H25: 93.18 | I25: 46.59 | J25: 101.47 | K25: 34.17 | L25: 101.47 | M25: 74.55 | N25: 101.47 | O25: 101.47 | P25: 136.28 | Q25: 93.18 | R25: 119.45 | S25: 101.47 | T25: 37.86 | U25: 101.47 | V25: 93.18 | W25: 87.61 | X25: 93.18 | Y25: 87.61 | Z25: 93.18 | AA25: 101.47 | AB25: 64.24 | AC25: 71.44 | AD25: 93.18 | AE25: 101.47 | AF25: 136.28 | AG25: 136.28 | AH25: 101.47 | AI25: 87.61 | AJ25: 101.47 | AK25: 3.38 | AM25: 126.18 | AN25: 87.61 | AO25: 101.47 | AP25: 101.47 | AQ25: 101.47 | AR25: 61.32 | AS25: 101.47 | AT25: 93.18 | AU25: 87.61 | AV25: 126.18 | AW25: 101.47 | AX25: 77.65 | AY25: 93.18 | AZ25: 87.61 | BA25: 101.47 | BC25: 87.61 | BD25: 69.89 | BE25: 101.47 | BG25: 87.61 | BH25: 93.18 | BI25: 87.61 | BJ25: 87.61 | BK25: 101.47 | BL25: 119.45 | BM25: 119.45 | BN25: 87.61 | BO25: 87.61 | BP25: 73.01 | BQ25: 87.61 | BR25: 93.18 | BS25: 101.47 | BT25: 126.18 | BU25: 87.61 | BV25: 58.4 | BW25: 93.18 | BX25: 101.47 | BY25: 93.18 | BZ25: 93.18 | CA25: 101.47 | CB25: 119.45 | CC25: 101.47 | CD25: 93.18 | CE25: 87.61 | CF25: 87.61 | CG25: 87.61 | CH25: 119.45 | CI25: 87.61 | CJ25: 87.61 | CK25: 87.61 | CL25: 87.61 | CM25: 87.61 | CN25: 87.61 | CO25: 2.92 | CP25: 87.61 | CR25: 87.61 | CS25: 87.61 | CT25: 78.85 | CU25: 87.61 | CV25: 87.61 | CW25: 87.61 | CY25: 87.61 | CZ25: 65.7 | DA25: 93.18 | DB25: 93.18 | DC25: 87.61 | DD25: 126.18 | DE25: 68.33 | DF25: 55.48 | DG25: 68.33 | DH25: 58.4 | DI25: 55.48 | DJ25: 55.48 | DK25: 37.27 | DL25: 10.15
B26: 187 | C26: PLUS NOCTURNITAT | D26: 55.6 | F26: 6.6 | G26: 0.29 | H26: 16.28 | J26: 1301.47 | K26: 21.74 | M26: 0.29 | Q26: 2.86 | W26: 63.76 | X26: 15.29 | Y26: 281.45 | AA26: 300 | AB26: 366.67 | AC26: 18.33 | AD26: 1.17 | AI26: 145.88 | AJ26: 250 | AK26: 3.5 | AN26: 92.91 | AQ26: 383.33 | AU26: 200 | AX26: 0.81 | AY26: 22.29 | BC26: 26.95 | BG26: 30.32 | BN26: 26.44 | BP26: 286.73 | BQ26: 15.4 | BS26: 100 | BU26: 60.24 | BW26: 136.22 | BX26: 145.2 | BY26: 0.84 | BZ26: 1.5 | CC26: 250 | CD26: 10.3 | CE26: 0.84 | CF26: 200 | CG26: 0.18 | CJ26: 4.69 | CK26: 4.47 | CL26: 2.82 | CN26: 289.23 | CR26: 0.07 | CS26: 4.55 | CT26: 241.56 | CU26: 4.03 | CW26: 258.68 | CY26: 11.22 | DA26: 19.98 | DB26: 1.39
B27: 197 | C27: A CTE CONVENI | D27: 142.31 | F27: 10.7 | G27: 510.13 | H27: 444.35 | I27: 415.97 | K27: 187.05 | M27: 173.57 | O27: 660.84 | P27: 195.18 | Q27: 314.27 | R27: 2328.51 | T27: 27.07 | V27: 828.46 | X27: 260.13 | Y27: 244.06 | Z27: 234.91 | AA27: 412.55 | AB27: 334.81 | AC27: 399.73 | AD27: 160.13 | AE27: 185.51 | AG27: 61.85 | AH27: 168.84 | AJ27: 235.51 | AK27: 6.67 | AM27: 438.57 | AN27: 304.91 | AO27: 985.51 | AP27: 746.77 | AQ27: 540.74 | AR27: 125.34 | AS27: 510.83 | AT27: 539.69 | AU27: 443.76 | AV27: 375.85 | AW27: 635.51 | AX27: 216.77 | AY27: 323.7 | AZ27: 144.06 | BC27: 94.06 | BE27: 244.17 | BG27: 19.06 | BH27: 426.8 | BJ27: 627.39 | BK27: 813.98 | BL27: 867.47 | BM27: 931.77 | BP27: 78.38 | BR27: 793.46 | BS27: 488.85 | BT27: 209.4 | BU27: 44.06 | BW27: 60.13 | BX27: 71.27 | BY27: 160.13 | BZ27: 110.13 | CA27: 763.99 | CB27: 927 | CC27: 219.13 | CD27: 160.13 | CE27: 244.06 | CF27: 594.06 | CG27: 344.06 | CH27: 1815.1 | CI27: 710.72 | CJ27: 919.06 | CK27: 106.58 | CL27: 206.58 | CM27: 106.58 | CO27: 3.55 | CP27: 106.58 | CU27: 327.41 | CV27: 2.41 | DA27: 60.13 | DB27: 60.13 | DC27: 377.39 | DD27: 1352.2 | DE27: 117.43 | DF27: 91.24 | DG27: 117.43 | DH27: 71.05 | DK27: 104.05 | DL27: 100.22
B28: 199 | C28: PART PROPORCIONAL VACANC | AK28: 1566.07
B29: 229 | C29: COMP NO COMPETENCIA | BM29: 333.33 | BT29: 541.67 | CB29: 375
B30: 262 | C30: OBJECTIU VARIABLE | BH30: 500
B31: 287 | C31: PAGA FIDELITAT | D31: 74.15 | E31: 74.46 | F31: 4.96 | G31: 74.15 | H31: 74.15 | I31: 37.08 | J31: 74.46 | K31: 27.19 | L31: 74.46 | M31: 59.32 | N31: 74.46 | O31: 74.46 | P31: 75.74 | Q31: 74.15 | R31: 75.12 | S31: 74.46 | T31: 22.61 | U31: 74.46 | V31: 74.15 | W31: 73.84 | X31: 74.15 | Y31: 73.84 | Z31: 74.15 | AA31: 74.46 | AB31: 54.15 | AC31: 56.85 | AD31: 74.15 | AE31: 74.46 | AF31: 75.74 | AG31: 75.74 | AH31: 74.46 | AI31: 73.84 | AJ31: 74.46 | AK31: 2.48 | AM31: 75.37 | AN31: 73.84 | AO31: 74.46 | AP31: 74.46 | AQ31: 74.46 | AR31: 51.69 | AS31: 74.46 | AT31: 74.15 | AU31: 73.84 | AV31: 75.37 | AW31: 74.46 | AX31: 61.79 | AY31: 74.15 | AZ31: 73.84 | BA31: 74.46 | BC31: 73.84 | BD31: 55.61 | BE31: 74.46 | BG31: 73.84 | BH31: 74.15 | BI31: 73.84 | BJ31: 73.84 | BK31: 74.46 | BL31: 75.12 | BM31: 75.12 | BN31: 73.84 | BO31: 73.84 | BP31: 61.53 | BQ31: 73.84 | BR31: 74.15 | BS31: 74.46 | BT31: 75.37 | BU31: 73.84 | BV31: 49.23 | BW31: 74.15 | BX31: 74.46 | BY31: 74.15 | BZ31: 74.15 | CA31: 72.29 | CB31: 75.12 | CC31: 74.46 | CD31: 74.15 | CE31: 73.84 | CF31: 73.84 | CG31: 73.84 | CH31: 75.12 | CI31: 73.84 | CJ31: 73.84 | CK31: 73.84 | CL31: 73.84 | CM31: 73.84 | CN31: 73.84 | CO31: 2.46 | CP31: 73.84 | CR31: 73.84 | CS31: 73.84 | CT31: 66.46 | CU31: 73.84 | CV31: 73.84 | CW31: 73.84 | CY31: 73.84 | CZ31: 55.38 | DA31: 74.15 | DB31: 74.15 | DC31: 73.84 | DD31: 75.37 | DE31: 54.38 | DF31: 46.77 | DG31: 54.38 | DH31: 49.23 | DI31: 46.77 | DJ31: 46.77 | DK31: 29.66 | DL31: 7.45
B32: 306 | C32: PLUS DISPONIBILI | AA32: 81.3
B33: 328 | C33: PLUS PRODUCTIV. | W33: 203.65 | Y33: 66.89 | AA33: 396.66 | AE33: 327.82 | AN33: 70.75 | AO33: 463.32 | AZ33: 100.07 | BG33: 337.46 | BP33: 131.88 | BS33: 120 | BW33: 135.73 | BZ33: 118.89 | CC33: 499.99 | CN33: 104.09 | CT33: 80.98 | CY33: 105.39 | DA33: 114.81
B34: 329 | C34: PLUS PRODUCTIV.2 | G34: 26 | H34: 50 | K34: 60 | Y34: 135 | AA34: 160 | AC34: 14 | AD34: 57 | AE34: 50 | AY34: 52 | BC34: 183 | BG34: 178 | BP34: 167 | BQ34: 178 | BU34: 178 | BV34: 242 | BZ34: 58 | CD34: 34 | CS34: 135 | CT34: 171 | CW34: 167 | DA34: 57 | DB34: 55
B35: 332 | C35: PLUS SAL VOLUNTARI | AG35: 2966.48
B36: 365 | C36: COMISSIONS | E36: 1638.71 | L36: 1285.23 | N36: 415.57 | O36: 1159.6 | S36: 1705.07 | U36: 1074.28 | AE36: 314.95 | AH36: 229.41 | AI36: 199.21 | BA36: 1447.37 | BE36: 1289.11 | BJ36: 533.49 | BL36: 19.33
B37: 397 | C37: PLUS DISTANCIA | D37: 33.12 | E37: 33.12 | F37: 2.21 | G37: 33.12 | H37: 33.12 | I37: 33.12 | J37: 33.12 | K37: 12.14 | L37: 33.12 | M37: 26.5 | N37: 33.12 | O37: 33.12 | P37: 33.12 | Q37: 33.12 | R37: 33.12 | S37: 33.12 | T37: 33.12 | U37: 33.12 | V37: 33.12 | W37: 33.11 | X37: 33.12 | Y37: 33.11 | Z37: 33.12 | AA37: 33.12 | AB37: 24.28 | AC37: 25.39 | AD37: 33.12 | AE37: 33.12 | AF37: 33.12 | AG37: 33.12 | AH37: 33.12 | AI37: 33.11 | AJ37: 33.12 | AK37: 1.1 | AM37: 33.12 | AN37: 33.11 | AO37: 33.12 | AP37: 33.12 | AQ37: 33.12 | AR37: 23.18 | AS37: 33.12 | AT37: 33.12 | AU37: 33.11 | AV37: 33.12 | AW37: 33.12 | AX37: 27.6 | AY37: 33.12 | AZ37: 33.11 | BA37: 33.12 | BC37: 33.11 | BD37: 33.12 | BE37: 33.12 | BG37: 33.11 | BH37: 33.12 | BI37: 33.11 | BJ37: 33.11 | BK37: 33.12 | BL37: 33.12 | BM37: 33.12 | BN37: 33.11 | BO37: 33.11 | BP37: 27.59 | BQ37: 33.11 | BR37: 33.12 | BS37: 33.12 | BT37: 33.12 | BU37: 33.11 | BV37: 22.07 | BW37: 33.12 | BX37: 33.12 | BY37: 33.12 | BZ37: 33.12 | CA37: 33.12 | CB37: 33.12 | CC37: 33.12 | CD37: 33.12 | CE37: 33.11 | CF37: 33.11 | CG37: 33.11 | CH37: 33.12 | CI37: 33.11 | CJ37: 33.11 | CK37: 33.11 | CL37: 33.11 | CM37: 33.11 | CN37: 33.11 | CO37: 1.1 | CP37: 33.11 | CR37: 33.11 | CS37: 33.11 | CT37: 29.8 | CU37: 33.11 | CV37: 33.11 | CW37: 33.11 | CY37: 33.11 | CZ37: 33.11 | DA37: 33.12 | DB37: 33.12 | DC37: 33.11 | DD37: 33.12 | DE37: 24.29 | DF37: 20.97 | DG37: 24.29 | DH37: 22.07 | DI37: 20.97 | DJ37: 20.97 | DK37: 13.25 | DL37: 3.31
B38: 450 | C38: PREST.MALALTIA CARGO EMP | F38: 489.6 | K38: 508.08 | M38: 35.15 | AC38: 91.56 | CO38: 375
B39: 451 | C39: MALALTIA | F39: 510 | K39: 84.68 | CO39: 429.67
B40: 452 | C40: ACCIDENTE | AK40: 1488.25 | AX40: 135.54 | BB40: 1756.16 | BP40: 140.91
B41: 455 | C41: COMPLEMENT I.T. | F41: 866.37 | K41: 476.05 | M41: 52.68 | AC41: 103.18 | AK41: 376.02 | AX41: 164.47 | BP41: 117.43 | CO41: 537.95
B42: 614 | C42: KM EXEMPT | BT42: 51.87 | CB42: 132.54
B43: 634 | C43: REGULARITZACIO | AI43: 25
...

Sheet 2
A2: Moneda: Euro
A3: PAGAMENT MENSUAL + LIQUIDACIÓ
A4: DEL 01/02/26 AL 28/02/26 | D4: TOTAL
A5: Empresa: 350-PEIXOS PUIGNAU S.A. NIF: A17216359 | D5: PEIXOS PUIGNAU S.A.
A9: CONCEPTE
B11: 1 | C11: SALARI BASE | D11: =SUM('1'!$D$11:$DM$11) -> 114848.27
B12: 13 | C12: OBERTURA NOVA BOTIGA | D12: =SUM('1'!$D$12:$DM$12) -> 80
B13: 74 | C13: PRESENCIA I IMATGE | D13: =SUM('1'!$D$13:$DM$13) -> 3382.01
B14: 75 | C14: PLUS PERILLOSITAT | D14: =SUM('1'!$D$14:$DM$14) -> 1658.95
B15: 84 | C15: PLUS UTILITZ I MANT.MÀQU | D15: =SUM('1'!$D$15:$DM$15) -> 108.37
B16: 85 | C16: PLUS RESPONSABILITAT | D16: =SUM('1'!$D$16:$DM$16) -> 3588.83
B17: 93 | C17: PLUS DISPONIBILITAT | D17: =SUM('1'!$D$17:$DM$17) -> 993.54
B18: 113 | C18: REGULARITZACIO | D18: =SUM('1'!$D$18:$DM$18) -> 1638.83
B19: 123 | C19: ACCIDENT CONVENI | D19: =SUM('1'!$D$19:$DM$19) -> 152.51
B20: 131 | C20: MILLORA SALARIAL ABSORBI | D20: =SUM('1'!$D$20:$DM$20) -> 15177.56
B21: 152 | C21: VEHICLE | D21: =SUM('1'!$D$21:$DM$21) -> 579.58
B22: 171 | C22: MILLORA VOLUNTARIA ABSOR | D22: =SUM('1'!$D$22:$DM$22) -> 946.44
B23: 173 | C23: PP PAGA ESTIU | D23: =SUM('1'!$D$23:$DM$23) -> 9473.42
B24: 174 | C24: PP PAGA NADAL | D24: =SUM('1'!$D$24:$DM$24) -> 9473.42
B25: 175 | C25: PP PAGA BENEFICIS | D25: =SUM('1'!$D$25:$DM$25) -> 9473.42
B26: 187 | C26: PLUS NOCTURNITAT | D26: =SUM('1'!$D$26:$DM$26) -> 5684.37
B27: 197 | C27: A CTE CONVENI | D27: =SUM('1'!$D$27:$DM$27) -> 31323.9
B28: 199 | C28: PART PROPORCIONAL VACANC | D28: =SUM('1'!$D$28:$DM$28) -> 1566.07
B29: 229 | C29: COMP NO COMPETENCIA | D29: =SUM('1'!$D$29:$DM$29) -> 1250
B30: 262 | C30: OBJECTIU VARIABLE | D30: =SUM('1'!$D$30:$DM$30) -> 500
B31: 287 | C31: PAGA FIDELITAT | D31: =SUM('1'!$D$31:$DM$31) -> 7242.65
B32: 306 | C32: PLUS DISPONIBILI | D32: =SUM('1'!$D$32:$DM$32) -> 81.3
B33: 328 | C33: PLUS PRODUCTIV. | D33: =SUM('1'!$D$33:$DM$33) -> 3378.38
B34: 329 | C34: PLUS PRODUCTIV.2 | D34: =SUM('1'!$D$34:$DM$34) -> 2407
B35: 332 | C35: PLUS SAL VOLUNTARI | D35: =SUM('1'!$D$35:$DM$35) -> 2966.48
B36: 365 | C36: COMISSIONS | D36: =SUM('1'!$D$36:$DM$36) -> 11311.33
B37: 397 | C37: PLUS DISTANCIA | D37: =SUM('1'!$D$37:$DM$37) -> 3287.32
B38: 450 | C38: PREST.MALALTIA CARGO EMP | D38: =SUM('1'!$D$38:$DM$38) -> 1499.39
B39: 451 | C39: MALALTIA | D39: =SUM('1'!$D$39:$DM$39) -> 1024.35
B40: 452 | C40: ACCIDENTE | D40: =SUM('1'!$D$40:$DM$40) -> 3520.86
B41: 455 | C41: COMPLEMENT I.T. | D41: =SUM('1'!$D$41:$DM$41) -> 2694.15
B42: 614 | C42: KM EXEMPT | D42: =SUM('1'!$D$42:$DM$42) -> 184.41
B43: 634 | C43: REGULARITZACIO | D43: =SUM('1'!$D$43:$DM$43) -> 25
B44: 988 | C44: IMP.INGR. A CTA. ESP. CG | D44: =SUM('1'!$D$44:$DM$44) -> 125.94
A46: TOTAL BRUT | D46: =SUM('1'!$D$46:$DM$46) -> 251648.05
...
